Workbook

Sheet Summary List
E2: Out of Total
B3: TRADE | E3: Number of Contractors | G3: Physical Shops | I3: Installation | K3: Import Supply | M3: Local Supply | O3: Delivery
B4: Maltese Balconies | E4: 0 | G4: 0 | I4: 0 | K4: 0 | M4: 0 | O4: 0
B5: Office Hardware | E5: =COUNTA(Hardware!B2:B40) -> 17 | G5: =COUNTIF(Hardware!H1:H18, "yes") & " out of " & E5 -> 9 out of 17 | I5: =COUNTIF(Hardware!G2:G18, "yes") & " out of " & E5 -> 16 out of 17 | K5: =COUNTIF(Hardware!K2:K18, "yes") & " out of " & E5 -> 17 out of 17 | M5: =COUNTIF(Hardware!J2:J18, "yes") & " out of " & E5 -> 17 out of 17 | O5: =COUNTIF(Hardware!I2:I18, "yes") & " out of " & E5 -> 17 out of 17
B6: Lasers | E6: =COUNTA(Laser!B2:B40) -> 1 | G6: =COUNTIF(Laser!H1:H18, "yes") & " out of " & E6 -> 1 out of 1 | I6: =COUNTIF(Laser!G2:G18, "yes") & " out of " & E6 -> 1 out of 1 | K6: =COUNTIF(Laser!J2:J8, "yes") & " out of " & E6 -> 0 out of 1 | M6: =COUNTIF(Laser!I2:I7, "yes") & " out of " & E6 -> 1 out of 1 | O6: =COUNTIF(Laser!H2:H7, "yes") & " out of " & E6 -> 1 out of 1
B7: Surveyors | E7: =COUNTA(Surveyors!B2:B40) -> 13 | G7: N/A | I7: N/A | K7: N/A | M7: N/A | O7: N/A
B8: Waterproofing | E8: =COUNTA(Waterproofing!B2:B40) -> 30 | G8: =COUNTIF(Waterproofing!H1:H40, "yes") & " out of " & E8 -> 30 out of 30 | I8: =COUNTIF(Waterproofing!G2:G32, "yes") & " out of " & E8 -> 8 out of 30 | K8: =COUNTIF(Waterproofing!K2:K41, "yes") & " out of " & E8 -> 8 out of 30 | M8: =COUNTIF(Waterproofing!J2:J41, "yes") & " out of " & E8 -> 22 out of 30 | O8: =COUNTIF(Waterproofing!I2:I41, "yes") & " out of " & E8 -> 30 out of 30
B9: Surface Finishes | E9: 0 | G9: 0 | I9: 0 | K9: 0 | M9: 0 | O9: 0
B10: Terrazzo Slabs | E10: =COUNTA('Terrazzo Slabs'!B2:B21) -> 12 | G10: =COUNTIF('Terrazzo Slabs'!H2:H30, "yes") & " out of " & E10 -> 9 out of 12 | I10: =COUNTIF('Terrazzo Slabs'!G2:G29, "yes") & " out of " & E10 -> 9 out of 12 | K10: =COUNTIF('Terrazzo Slabs'!K2:K31, "yes") & " out of " & E10 -> 7 out of 12 | M10: =COUNTIF('Terrazzo Slabs'!J2:J31, "yes") & " out of " & E10 -> 10 out of 12 | O10: =COUNTIF('Terrazzo Slabs'!I2:I31, "yes") & " out of " & E10 -> 12 out of 12
B11: Washing Machines | E11: =COUNTA('Washing Machines'!B2:B30) -> 23 | G11: =COUNTIF('Washing Machines'!H2:H31, "yes") & " out of " & E11 -> 19 out of 23 | I11: =COUNTIF('Washing Machines'!G2:G31, "yes") & " out of " & E11 -> 19 out of 23 | K11: =COUNTIF('Washing Machines'!K2:K31, "yes") & " out of " & E11 -> 23 out of 23 | M11: =COUNTIF('Washing Machines'!J2:J31, "yes") & " out of " & E11 -> 23 out of 23 | O11: =COUNTIF('Washing Machines'!I2:I24, "yes") & " out of " & E11 -> 21 out of 23
B12: Tumble Dryer | E12: =COUNTA('Tumble Dryer'!B2:B31) -> 17 | G12: =COUNTIF('Tumble Dryer'!H2:H31, "yes") & " out of " & E12 -> 16 out of 17 | I12: =COUNTIF('Tumble Dryer'!G2:G31, "yes") & " out of " & E12 -> 17 out of 17 | K12: =COUNTIF('Tumble Dryer'!J2:J31, "yes") & " out of " & E12 -> 17 out of 17 | M12: =COUNTIF('Tumble Dryer'!J2:J31, "yes") & " out of " & E12 -> 17 out of 17 | O12: =COUNTIF('Tumble Dryer'!K2:K31, "yes") & " out of " & E12 -> 17 out of 17
B13: Gypsum | E13: =COUNTA(Gypsum!B2:B31) -> 22 | G13: =COUNTIF(Gypsum!H2:H31, "yes") & " out of " & E13 -> 17 out of 22 | I13: =COUNTIF(Gypsum!G2:G31, "yes") & " out of " & E13 -> 5 out of 22 | K13: =COUNTIF(Gypsum!I2:I31, "yes") & " out of " & E13 -> 22 out of 22 | M13: =COUNTIF(Gypsum!J2:J31, "yes") & " out of " & E13 -> 17 out of 22 | O13: =COUNTIF(Gypsum!K2:K31, "yes") & " out of " & E13 -> 5 out of 22
B14: Site Clearance | E14: =COUNTA('Site Clearance'!B2:B31) -> 2 | G14: N/A | I14: N/A | K14: N/A | M14: N/A | O14: N/A
B15: Industrial Shelving | E15: =COUNTA('Industrial Shelving'!B2:B31) -> 15 | G15: =COUNTIF('Industrial Shelving'!G2:G31, "yes") & " out of " & E15 -> 15 out of 15 | I15: =COUNTIF('Industrial Shelving'!H2:H31, "yes") & " out of " & E15 -> 14 out of 15 | K15: =COUNTIF('Industrial Shelving'!I2:I31, "yes") & " out of " & E15 -> 15 out of 15 | M15: =COUNTIF('Industrial Shelving'!J2:J31, "yes") & " out of " & E15 -> 0 out of 15 | O15: =COUNTIF('Industrial Shelving'!K2:K31, "yes") & " out of " & E15 -> 15 out of 15
B16: Multisensory Rooms | E16: =COUNTA('multysensory room'!B3:B31) -> 5 | G16: =COUNTIF('multysensory room'!G2:G31, "yes") & " out of " & E16 -> 5 out of 5
B17: Bathrooms
B18: Bedrooms
B19: Kitchens
B20: Wall Panels
B21: Office Furniture

Sheet Fibreglass
A1: item | B1: supplier | C1: email | D1: phone number | E1: location | F1: website | G1: notes
C2: info@micalleffibreglassworks.com
C3: info@silvercraftltd.com
C4: etienne@silvercraftltd.com
C5: angela@silvercraftltd.com
C6: info@crownfibreglass.com
C7: info@micallefpools.com
B8: Glassfibre Industries | C8: natasha@glassfibreindustries.net | D8: 21470282 | E8: Birkirkara | F8: http://www.glassfibreindustries.net/?utm_source=Yellow&utm_medium=Yellow-Website&utm_campaign=Landing-Page
B9: Crown Fibreglass | C9: info@crownfibreglass.com | D9: 99 420 586 | E9: Zetjun | F9: http://www.crownfibreglass.com/?utm_source=Yellow&utm_medium=Yellow-Website&utm_campaign=Landing-Page
B10: Silvercraft Products Ltd | C10: info@silvercraftltd.com | D10: 21 898 046 | E10: Marsa | F10: http://www.silvercraftltd.com/?utm_source=Yellow&utm_medium=Yellow-Website&utm_campaign=Landing-Page
B11: Fashion Fibreglass | C11: fashionfibre@hotmail.com | D11: 21 485 748 | E11: Qormi
B12: Seabrave Marine | C12: info@seabravemarine.com | D12: 7905 0545 | E12: Birzebbugia | F12: https://www.facebook.com/people/Seabrave-Marine/100057368593400/

Sheet Extractors
A1: c | B1: supplier | C1: email | D1: phone number | E1: location | F1: website
A2: Ventilation | B2: Econova | C2: econovamalta@gmail.com | D2: 9942 1158 | E2: 50, Triq Salvu Psaila, Birkirkara, Malta, BKR9072 | F2: https://www.facebook.com/econovamalta/ | G2: Wants us to book a consultation (but costs 50euro for them to come on site) https://docs.google.com/forms/d/e/1FAIpQLSeB6v8JWo79RIujHFRtUz1Z2D1YFwtXp6QogrjMGIh5-JjSqw/viewform
A3: Ventilation | B3: Titan
A4: Ventilation | B4: HVAC | C4: info@hvacsupplies.eu | D4: 9999 4570 | E4: Triq Ħal Luqa, Qormi, QRM 9070, Malta | F4: https://hvacsupplies.eu/about-us/
A5: Ventilation | B5: Cutrico | C5: info@cutrico.com | D5: 2149 8658 | E5: Cutrico Ltd, Mriehel By-pass, Mriehel, Malta | F5: https://www.cutrico.com/en/home.htm
A6: Ventilation | B6: Comfortek | C6: dpcomfortek@gmail.com | D6: 2143 7403 | E6: 94 Triq wied hal-Balzan, Balzan, Malta | F6: comfortek.mt
A7: Ventilation | B7: Bezzina Bros | C7: info@bezzbros.com | D7: 2123 1892 | E7: Aldo Moro Rd., Marsa, Malta, MRS9065 | F7: https://bezzbros.com/
A8: Ventilation | B8: GI Maintenance
A9: Ventilation | B9: C&D Electrical & Mechanical Installations | C9: info@cdinstallations.com.mt | D9: 79206640 | E9: 28, Triq Borg, Fleur-De-Lys, Birkirkara, BKR 4963 | F9: https://www.cdinstallations.com.mt/
A10: Ventilation | B10: Energex | C10: energexservices@gmail.com | D10: 9947 6119
A11: Ventilation | B11: Cooltec | C11: info@cooltekservices.com.mt | F11: https://cooltekservices.com.mt/contact-us/
A12: Ventilation | B12: DR Installations | C12: rosamonddesira@gmail.com
A13: Ventilation | B13: CE Installations | C13: info@ceinstallations.com.mt | D13: 2767 7822 | F13: https://ceinstallations.com.mt/
A14: Ventilation | B14: WeDuct | C14: info@weduct.com.mt
A15: Ventilation | B15: Proklima | C15: projects@proklimamalta.com | D15: 99 401 247 | E15: Garage V15 Warehouse First Floor, Binja San Guzepp Haddiem Triq Indri Psaila Qormi | F15: https://www.proklimamalta.com/
A16: Ventilation | B16: Midea Malta | C16: sales@midea.mt | D16: 7966 7908 | F16: https://midea.mt/contact/
A17: Ventilation | B17: Callejja | C17: webshop@calleja.com.mt | F17: https://calleja.com.mt/contact/
A18: Ventilation | B18: Tabone Direct | C18: sales@tabonedirect.com
A19: Ventilation | B19: Geoholistic | C19: info@geoholistic.com | D19: 21370404 | E19: Geo Holistic Co. Ltd. G1, Five Star Business Park, Triq il-Belt Valletta, Ghaxaq | F19: https://www.geoholistic.com/ventilation.html
A20: Ventilation | B20: RS | C20: sales@thetccgroup.org
A21: Ventilation | B21: MFF Industrial Supplies | C21: sales@mff-isl.com
A22: Ventilation | B22: Smart Effects | C22: afenech@smarteffects.com.mt
B26: MV System
B27: Nonstop forced cross ventilation
B28: You need a fresh air system together with the ac unit
B30: We need to draft up an email to these guys to tell us what our options are.
B32: Econova is suggesting a tailored ventilation system (we need enough height in the room).
B33: They intall a bulkhead (to hide the ventilation pipes) and created a filtrated ventilation system.

Sheet Handyman
A1: item | B1: name | C1: email | D1: phone number | E1: location | F1: website | G1: Corporate/Self Employed | H1: Note
A3: Handyman | B3: Mr. Handy | C3: info@mrhandy.mt | D3: 2733 0364 | E3: 682, Triq il-Kbira San Ġużepp, Ħamrun, Malta | F3: briiz.com.mt/handyman | G3: Corporate
A4: Handyman | B4: Ewi home services Limited | C4: info@ewihomeservices.com | D4: 7922 1982 | E4: Registered in Malta (Service area: All Malta, no public storefront) | F4: ewihomeservices.com | G4: Corporate
A5: Handyman | B5: WS Installations | C5: info@wsinstallations.com | D5: 9965 5581 | E5: Triq Ċensu Busuttil, L-Iklin | F5: https://www.wsinstallationsmalta.com/ | G5: Corporate
A6: Handyman | B6: Handyman Solutions Ltd | C6: ilenia@actsmart.com.mt | D6: 7713 1210 | E6: 58c, Triq Patri Feliċjan Bilocca, Marsa | F6: N/A | G6: Corporate
A7: Handyman | B7: 24/7 Handyman Services (Kevin Bonnici) | C7: kevin.bonnici76@gmail.com | D7: 9911 1247 | E7: Registered in Qormi (Mobile contractor, no public storefront) | F7: N/A | G7: Self-Employed
A8: Handyman | B8: Homecare Malta | C8: info@homecaremalta.com | D8: 2152 9528 | E8: 881, Triq il-Kbira San Ġużepp, Ħamrun, HMR 1010 | F8: homecaremalta.com | G8: Corporate
A9: Handyman | B9: J D Maintenance & High-Up | C9: demicolijo@gmail.com | D9: 9947 5511 | E9: Registered in Mosta (Mobile contractor, no public storefront) | F9: N/A | G9: Self-Employed | H9: Agreed to the tems. Self-Employed, just one worker
A10: Handyman | B10: NLP Force Ltd | C10: nikola.pejovic@nlpforce.com | D10: 9958 0909 | E10: Triq Ġużeppi Xuereb ix-Xhudi, Swatar, Birkirkara | F10: nlpforce.com | G10: Corporate
A11: Handyman | B11: Joseph's Handy Solutions | C11: schembrijoseph91@gmail.com | D11: 7709 8188 | E11: Registered in Żejtun (Mobile contractor, no public storefront) | F11: N/A | G11: Self-Employed
A12: Handyman | B12: AB Installations By Formosa | C12: abinstallationsbyformosa@gmail.com | D12: 7929 9918 | E12: Registered in Żabbar (Mobile contractor, no public storefront) | F12: N/A | G12: Self-Employed
A13: Handyman | B13: Marco Vella Handyman Services | C13: Contact via website form | D13: 7900 0000 | E13: 31, Triq il-Merill, Mellieħa, MLH 2572 | F13: marcovella.com | G13: Corporate
A14: Handyman | B14: Briiz (Mr. Handyman) | C14: info@briiz.com.mt | D14: 2733 0364 | E14: 682, Triq il-Kbira San Ġużepp, Ħamrun, Malta | F14: briiz.com.mt/handyman | G14: Corporate
A15: Handyman | B15: Swift Solutions | C15: swiftsolution2025@gmail.com | D15: 9907 4325 | E15: Registered in Mosta (Service area: All Malta, no public storefront) | F15: N/A | G15: Self-Employed
A16: Handyman | B16: Better Call Tyrone | C16: tyrone.vassallo01@gmail.com | D16: 7944 2574 | E16: Registered in Qormi (Mobile contractor, no public storefront) | F16: N/A | G16: Self-Employed | H16: Reqiures a meeting to discuss further
A17: Handyman | B17: JC Handyman & Turnkey | C17: jason.cordina79@gmail.com | D17: 7982 7981 | E17: 176, Triq San Bastjan, Qormi | F17: N/A | G17: Self-Employed
A18: Handyman | B18: ZAG - Services & Finishes Malta | C18: ZAGinfo@gmail.com | D18: 7777 9098 | E18: 373, St Joseph High Street, Mosta | F18: N/A | G18: Corporate
A19: Handyman | B19: ACM Maintanace | C19: clivesammut@hotmail.co.uk | D19: 7905 5452 | E19: 45, Indri Borg Street, Rabat | F19: N/A | G19: Self-Employed
A20: Handyman | B20: EC Installations | C20: esteliocini@gmail.com | D20: 7999 3858 | E20: 152, St. Peter Paul, Triq il-Kbira, Qormi | F20: N/A | G20: Self-Employed
A21: Handyman | B21: GF Installations | C21: gfinstallations@gmail.com | D21: 2765 6533 | E21: Garage 64, Triq is-Sajjied, Qawra, San Pawl il-Baħar | F21: gfonlinestore.com | G21: Corporate
A22: Handyman | B22: Brian Handyman & Gypsum Works | C22: brifor06@hotmail.com | D22: 9982 5505 | E22: Registered in Tarxien (Mobile contractor, no public storefront) | F22: N/A | G22: Self-Employed
A23: Handyman | B23: Gino Handyman Service | C23: gino.bonnici.11@gmail.com | D23: 7905 1396 | E23: Registered in Żejtun (Mobile contractor, no public storefront) | F23: N/A | G23: Self-Employed
A24: Handyman | B24: MB Handyman Services | C24: mb.handymanservice@libero.it | D24: 9972 6390 | E24: Registered in Buġibba / St. Paul's Bay (Mobile contractor, no public storefront) | F24: N/A | G24: Self-Employed
A25: Handyman | B25: Emilio Bilocca Handyman Services | C25: info@emiliohandyman.com | D25: N/A | E25: 17 Madonnina, Triq il-Pluvieri, Gudja (Also lists: Milicent Garage, Triq il-Magħsar, Gudja) | F25: emiliohandyman.com | G25: Self-Employed | H25: Chanrges 40EUR/hr Per Person
A26: Handyman | B26: Manutek | C26: Manutek@kompleto.com.mt | D26: 2702 8282 | E26: GPL Business Centre, Office 1, Level 2, Sqaq il-Ghadam, Mriehel, BKR3000 | F26: www.kompleto.com.mt | G26: Corporate
A27: Handyman | B27: Pj Handyman | C27: pjhandyman@mail.com | D27: 7928 8241 | E27: Registered in Qormi (Mobile contractor, no public storefront) | F27: N/A | G27: Corporate | H27: Does not work on fixed rates but by quote on site.
A28: Handyman
A29: Handyman
A30: Handyman
A31: Handyman
A32: Handyman
A33: Handyman
A34: Handyman
A35: Handyman
A36: Handyman
A37: Handyman

Sheet Electricians
A1: item | B1: name | C1: email | D1: phone number | E1: location | F1: website | G1: Corporate/Self Employed | H1: Note
A3: Electrician | B3: Aaron Agius | C3: aaronagius82@gmail.com | D3: 7926 2384 | E3: Id-Dwejra, Triq il-Fidwa, Gudja, Malta | F3: N/A | G3: Self-Employed
A4: Electrician | B4: Anthony D'Anastasi | C4: danastasi.rt@outlook.com | D4: 9948 5960 | E4: 32 Virgo, Triq il-Battaljun, Mosta, MST 2721, Malta | F4: N/A | G4: Self-Employed
A5: Electrician | B5: Aaron Zammit | C5: N/A | D5: 7920 0196 | E5: Cawsli Court, Flt 4, Triq L-Imdina, Ħal Qormi, Malta | F5: N/A | G5: Self-Employed
A6: Electrician | B6: Better Call Tyrone | C6: tyrone.vassallo01@gmail.com | D6: 7944 2574 | E6: Registered in Qormi (Mobile contractor, no public street address listed) | F6: N/A | G6: Self-Employed
A7: Electrician | B7: Stefan (AC's By Stefan) | C7: N/A | D7: N/A | E7: Registered in Malta (Mobile contractor, no public street address listed) | F7: N/A | G7: Self-Employed
A8: Electrician | B8: Dorian Sciortino | C8: Contact via REWS registry | D8: N/A | E8: Blk C6 Flat 2, Triq il-Fraxxnu, Ħaż-Żebbuġ, Malta | F8: N/A | G8: Self-Employed
A9: Electrician | B9: HandySalv | C9: Contact via StarOfService directory | D9: N/A | E9: Registered in Birżebbuġa, BBG 1606, Malta (Mobile contractor) | F9: N/A | G9: Self-Employed
A10: Electrician | B10: Roderick Attard | C10: N/A | D10: 9947 6137 | E10: Registered in Central Malta (Mobile domestic electrician) | F10: N/A | G10: Self-Employed
A11: Electrician | B11: Michelle Colombo | C11: N/A | D11: 9942 3371 | E11: 92 Triq Blanche Huber, Sliema, Malta | F11: N/A | G11: Self-Employed
A12: Electrician | B12: Salvu Fenech Ta' Spekna | C12: salvufenech@gmail.com | D12: 7949 7456 | E12: 39 Siskina, Triq Raddet Ir-Roti, Mosta, Malta | F12: N/A | G12: Self-Employed
A13: Electrician | B13: Carmel Carabott | C13: N/A | D13: 7920 4466 | E13: Registered in Marsaxlokk (Mobile domestic electrician) | F13: N/A | G13: Self-Employed
A14: Electrician | B14: JC Electrical Plumbing Installation | C14: jcelectricalmalta@gmail.com | D14: 7909 3306 | E14: Registered in Qormi (Mobile contractor) | F14: N/A | G14: Self-Employed
A15: Electrician | B15: Stephen Micallef (Electrical & Plumbing) | C15: N/A | D15: 9982 4815 | E15: Registered in Naxxar (Mobile contractor) | F15: N/A | G15: Self-Employed
A16: Electrician
A17: Electrician
A18: Electrician
A19: Electrician
A20: Electrician
A21: Electrician
A22: Electrician
A23: Electrician
A24: Electrician
A25: Electrician
A26: Electrician
A27: Electrician
... A37: Electrician

Sheet Carpenters
A1: item | B1: name | C1: email | D1: phone number | E1: location | F1: website
A2: Carpenter | B2: Domestica | C2: info@domestica.com.mt | F2: https://domestica.com.mt
A3: Carpenter | B3: FV Carpentry | C3: fran@fvcarpentry.com | F3: https://www.fvcarpentry.com
A4: Carpenter | B4: Refalo Woodworks Ltd | C4: info@refalowoodworksltd.com | F4: https://refalowoodworks.com
A5: Carpenter | B5: Gauci Woodworks | C5: pdgl1969@gmail.com | F5: https://www.findit.com.mt/en/directory/listings/3682/gauci-woodworks.htm
A6: Carpenter | B6: BP Woodworks | C6: info@bpwoodworks.com | F6: https://www.bpwoodworks.com
A7: Carpenter | B7: Armstrong Woodworks Ltd | C7: info@armstrong.com.mt | F7: https://www.armstrong.com.mt
A8: Carpenter | B8: Shalom Woodworks | C8: sales@shalomwoodworks.com | F8: https://www.shalomwoodworks.com
A9: Carpenter | B9: Joseph Briffa Woodworks | C9: joseph.briffa.woodworks@hotmail.com | F9: —
A10: Carpenter | B10: Jomasero Woodworks | C10: joseph.taekwondo@gmail.com | F10: —
A11: Carpenter | B11: Baldacchino Woodworks Ltd | C11: info@baldacchinogroup.com | F11: https://baldacchinogroup.com/left-menu/woodworks.html

Sheet Second Hand Car Dealers
A1: item | B1: name | C1: email | D1: phone number | E1: location | F1: website
A2: Car Dealer | B2: A&A | C2: info@aacarimports.com.mt | F2: https://aacarimports.com.mt/
A3: Car Dealer | B3: A1 Autodealers | C3: dowlinga@go.net.mt | F3: https://www.yellow.com.mt/a-1-auto-dealers_auto-dealers+mosta/
A4: Car Dealer | B4: ABS Auto Dealer | C4: abs@onvol.net | F4: https://www.facebook.com/p/ABS-Auto-Dealer-100057348224337/
A5: Car Dealer | B5: AJ Motors | C5: ajmotorsales@gmail.com | F5: https://www.yellow.com.mt/aj-motors/auto-dealers/
A6: Car Dealer | B6: Alan Motors | C6: info@alanmotors.com.mt | F6: https://alanmotors.com.mt/
A7: Car Dealer | B7: Attard Auto Dealer | C7: attardautodealer@gmail.com | D7: 9949 4186 | F7: https://www.facebook.com/p/Attard-Auto-Dealer-100057253586326/
A8: Car Dealer | B8: Attards Motors | C8: taattardmotors@gmail.com | D8: 7990 2106 | F8: https://www.facebook.com/attardsmotors/
A9: Car Dealer | B9: AutoGama | D9: 9945 4154 | F9: https://www.facebook.com/autogamaimports/
A10: Car Dealer | B10: Autozone Autodealer | C10: autozoneautodealer@gmail.com | F10: https://www.facebook.com/autozonemalta/
A11: Car Dealer | B11: Avis Malta | C11: info@aviscarsales.mt | F11: https://www.facebook.com/AvisMaltaUsedCarSales/
A12: Car Dealer | B12: Brincat Auto Imports | C12: info@brincatautoimports.com | F12: https://brincatautoimports.com/
A13: Car Dealer | B13: BTL Autodealer | C13: btlautodealer@gmail.com | D13: 9925 2716 | F13: https://www.facebook.com/Btlautodeater/
A14: Car Dealer | B14: Canadis Autodealer | C14: canadisautodealer@gmail.com | F14: https://www.facebook.com/p/Canadis-Auto-Dealer-100063715533716/
A15: Car Dealer | B15: CarHub | C15: info@carhub.mt | F15: https://www.facebook.com/carhubmalta/
A16: Car Dealer | B16: Caromotors | D16: 9903 0870 | F16: https://www.facebook.com/Caromotors/
A17: Car Dealer | B17: Cars and More | C17: info@cam.com.mt | F17: https://www.facebook.com/carsandmoremalta
A18: Car Dealer | B18: Cars Unlimited | C18: info@carsunlimitedmalta.com | F18: https://carsunlimitedmalta.com/
A19: Car Dealer | B19: Charlie Auto Dealer | D19: 9949 4553 | F19: https://www.facebook.com/p/Charlie-Auto-Dealer-100054340519565/
A20: Car Dealer | B20: Chevron Auto Dealer | C20: sales@chevronautodealer.mt | F20: https://www.facebook.com/ChevronCarsAndmore/
A21: Car Dealer | B21: CR Cars | C21: sales@fordsparesmalta.com | F21: https://www.facebook.com/crcarsmalta/
A22: Car Dealer | B22: D & G Auto Dealer | D22: 77 474 746
A23: Car Dealer | B23: D & S Auto Dealer | C23: dandsautodealer@hotmail.com | D23: 9947 7956 | F23: https://www.facebook.com/dandsautodealer/
A24: Car Dealer | B24: DC Motors | C24: dcmotorsbkara@gmail.com | D24: 9975 5547 | F24: https://www.facebook.com/p/DC-motors-Auto-Sales-100057442128124/
A25: Car Dealer | B25: Dino's Motor Centre | C25: dinosreception@gmail.com | D25: 21485301 | E25: Dino's Motor Centre, Mosta Road, Lija. LJA9012. | F25: https://dinosmotors.com/contact-form/
A26: Car Dealer | B26: Drive Automotive Co Ltd | C26: info@drive.com.mt | F26: https://www.facebook.com/DriveAutomotiveCoLtd/
A27: Car Dealer | B27: DRM Auto Sales | C27: philmar87@hotmail.co.uk | F27: https://www.facebook.com/p/DRM-Autosales-100054512857141/
A28: Car Dealer | B28: Emotion Car Imports | C28: sales@emotionimports.com | F28: https://www.facebook.com/EmotionImports/
A29: Car Dealer | B29: Eucharist Mercieca Auto Ltd | C29: info@emauto.com.mt | F29: https://www.facebook.com/emautoltd/
A30: Car Dealer | B30: Fava Auto Dealers | C30: clivefava@gmail.com | F30: https://www.facebook.com/favacardealers/
A31: Car Dealer | B31: Galea General Services Ltd (GGS) | C31: info@ggs.com.mt | F31: https://www.facebook.com/GaleaGeneralServicesLtd/
A32: Car Dealer | B32: Gasan Enterprises Ltd | C32: automotive@gasan.com
A33: Car Dealer | B33: Gauci Automobiles Co Ltd | C33: sales@gauciautomobiles.com
A34: Car Dealer | B34: George and Rocco Car Centre | C34: rocco@georgeandrocco.com | F34: https://www.facebook.com/georgeandroccocarcentre/?locale=mt_MT
A35: Car Dealer | B35: George Autodealer | C35: georgeautodealer95@gmail.com
A36: Car Dealer | B36: Glenn's Highway Auto Dealer | C36: highwayauto@onvol.net
A37: Car Dealer | B37: Horace Auto Dealer | C37: craigscicluna@gmail.com
A38: Car Dealer | B38: J Auto Malta | C38: jautoimports@gmail.com
A39: Car Dealer | B39: J C Car Sales | C39: jeanpazzopardi@gmail.com
A40: Car Dealer | B40: J F Motors | C40: jfmotorsgozo@gmail.com
...

Sheet Archaeological Monitors
A1: item | B1: name | C1: email | D1: phone number | E1: location | F1: website
A2: Monitor | B2: Ader Charlene | C2: arkeomalta@gmail.com | D2: 79621262
A3: Monitor | B3: Besancon Jeremy | C3: jeremy@jbarchteam.com | D3: 79289569
A4: Monitor | B4: Bossini Samuela | C4: samuelabossini@gmail.com | D4: 77882898
A5: Monitor | B5: Borg Marlene | C5: ascoopltdmalta@gmail.com | D5: 99872954
A6: Monitor | B6: Borg Daniel | C6: ascoopltdmalta@gmail.com | D6: 79277408
A7: Monitor | B7: Busuttil Christopher | C7: chrisbu.su@gmail.com | D7: 99256349
A8: Monitor | B8: Cachia Karl | C8: karloco621@gmail.com | D8: 99275364
A9: Monitor | B9: Calleja Joseph | C9: ascoopltdmalta@gmail.com | D9: 79538973
A10: Monitor | B10: Cardona David | C10: skavarc@digiarc.mt | D10: 99822803
A11: Monitor | B11: Caruana Josef | C11: josefcaruana1@googlemail.com | D11: 79092230
A12: Monitor | B12: Cassar Chantal | C12: projects@aecmalta.com.mt | D12: 79254003
A13: Monitor | B13: Cherubini Rossano | C13: rossano.cherubini@qpml.com | D13: 99502126
... A35: Monitor | B35: Zarb Martina | C35: martinazarb@gmail.com | D35: 99192609

Sheet Maltese Balconies
A1: item | B1: name | C1: email | D1: phone number | E1: location | F1: website

Sheet Wall Mounted Speakers
A1: Item | B1: Supplier | C1: Email | D1: Phone number | E1: Location | F1: Website | G1: Physical store | H1: Installations
A2: Wall mounted speakers | B2: Powerhouse Malta | C2: nfo@powerhousemalta.com | D2: 356 79 499 432 | E2: Marsa | F2: Powerhouse Malta – AV (Audiovisuals) and Events Malta | G2: yes | H2: yes
A3: wall mounted sspakers | B3: Scan | C3: info@scanmalta.com
A4: Wall mounted speakers | B4: A to Z | C4: marketing@atoz.com.mt | D4: 356 99319111 | E4: Attard, Qormi, Swatar, Birkirkara | F4: AtoZ Electronics | Malta's Shop of Choice in 2026! | G4: yes | H4: yes
A5: Wall mounted speakers | B5: Digital Zone | C5: info@digitalzone.com.mt
A6: Wall mounted speakers | B6: Olimpus | C6: info@olimpusmusic.com
A7: Wall mounted speakers | B7: DONEO CO LTD | C7: nfo@doneo.com.mt | D7: 356 21 230 741 | E7: Hamrun | F7: Home page - Doneo | G7: yes | H7: yes
A8: Wall mounted speakers | B8: ASTRAL Enterprises LTD | C8: website@astral.com.mt | D8: 356 21340562 | E8: Ta' Xbiex | F8: ASTRAL Enterprises LTD | TV | Hifi | Custom Installations | G8: yes | H8: yes
A9: Wall mounted speakers | B9: AUDIO Malta | C9: info@audiomalta.com | D9: 356 2138 2876 | E9: Swieqi | F9: Audio Malta – Shop Smart, Rent Easy | G9: yes | H9: yes
A10: Wall mounted speakers | B10: Audio Hub Malta | C10: info@audiohub.mt | D10: 356 99 495 428 | E10: sales division of Lito’s Place | F10: Audio Hub Malta – Acoustics & Audio Equipment | G10: no | H10: yes
A11: Wall mounted speakers | B11: Futuretech pro Malta | C11: info@futuretech-malta.com | D11: 356 2799 2315 | E11: San Gwann | F11: Futuretech Pro Malta – Audio/Visual Specialists | G11: yes | H11: yes
A12: Wall mounted Speakers | B12: Audiotech | C12: info@audiotech.mt | D12: 356 21560719 | E12: Xghara, Gozo | F12: Audiotech Malta - your local electronics shop for Malta and Gozo - we deliver | G12: yes | H12: no
A13: Wall mounted speakers | B13: Ultimate Malta | C13: sales@ultimate.com.mt | D13: 356 21 444 545 | E13: San Gwann, Paola, Qormi | F13: Homepage - Ultimate | Electronics | Home Appliances | Deliveries in Malta & Gozo | G13: yes | H13: yes
A14: Wall mounted speakers | B14: studio7 | C14: info@studioseven.com.mt | D14: 356 2148 6301 | E14: Birkirkara | F14: Studo7.com.mt | G14: no | H14: yes
A15: Wall mouunted Speakers | B15: Genaudio Ltd | C15: joe@genaudiomalta.com | D15: 356 2145 9966 | E15: Birkirkara | F15: Contact – Genaudio Ltd | G15: yes | H15: yes
A16: Wall mounted speakers | B16: The sound system Co Ltd | C16: info@soundsystem.com.mt | D16: 356 21 25 55 00 | E16: Msida | F16: The sound system you need | The Sound System Malta | G16: yes | H16: yes
A17: wall mounted speakers | B17: Megatekk | C17: info@megatekk.mt
A18: Wall mounted speakers | B18: Audiophonic | C18: jc.audiophonic@gmail.com

Sheet Hardware
A1: item | B1: supplier | C1: email | D1: phone number | E1: location | F1: website | G1: physical store | H1: installation | I1: delivery | J1: local supply | K1: import
A2: Compact monitor bracket | B2: SCAN | C2: info@scanmalta.com | G2: yes | H2: yes | I2: yes | J2: yes | K2: yes
A3: Compact monitor bracket | B3: Klikk | C3: sales@klikk.com.mt | G3: yes | H3: yes | I3: yes | J3: yes | K3: yes
A4: Compact monitor bracket | B4: Game Breaker | C4: info@gamebreakermalta.com | G4: yes | H4: no | I4: yes | J4: yes | K4: yes
A5: Compact monitor bracket | B5: AtoZ | C5: marketing@atoz.com.mt | G5: yes | H5: yes | I5: yes | J5: yes | K5: yes
A6: Compact monitor bracket | B6: Xpert | C6: sales@xpert.mt | G6: yes | H6: no | I6: yes | J6: yes | K6: yes
A7: Compact monitor bracket | B7: Computer Bargains | C7: info@computerbargainsmalta.com | G7: yes | H7: no | I7: yes | J7: yes | K7: yes
A8: Compact monitor bracket | B8: HomeMate | C8: customercare@homemate.com.mt | G8: yes | H8: yes | I8: yes | J8: yes | K8: yes
A9: Compact monitor bracket | B9: MaltaZon | C9: info@maltazon.com | G9: yes | H9: no | I9: yes | J9: yes | K9: yes
A10: Compact monitor bracket | B10: Forestals | C10: info@forestals.com | G10: yes | H10: yes | I10: yes | J10: yes | K10: yes
A11: Compact monitor bracket | B11: Top Choice | C11: info@topchoice.com.mt | G11: yes | H11: yes | I11: yes | J11: yes | K11: yes
A12: Compact monitor bracket | B12: Digital Zone | C12: info@digitalzone.com.mt | G12: yes | H12: no | I12: yes | J12: yes | K12: yes
A13: Compact monitor bracket | B13: Intercomp | C13: infosales@intercomp.com.mt | G13: yes | H13: yes | I13: yes | J13: yes | K13: yes
... A18: Compact monitor bracket | B18: The Notebook Center | C18: info@thenotebookcentre.com.mt | G18: yes | H18: no | I18: yes | J18: yes | K18: yes

Sheet Laser
A1: item | B1: supplier | C1: email | D1: phone number | E1: location | F1: website | G1: physical store | H1: delivery | I1: local supply | J1: import
A2: laser | B2: WJA Distributor | C2: info@wjadistributors.com | D2: 21809426 | E2: Dejma Road, Tarxien | F2: https://www.wjadistributors.com/product/bosch-cross-line-laser-advancedlevel-360/ | G2: yes | H2: yes | I2: yes | J2: no

Sheet Surveyors
A1: item | B1: supplier | C1: email | D1: phone number | E1: location | F1: website | G1: notes
A2: surveyor | B2: GeoMatix | C2: info@surveyingmalta.com | D2: 27440103 / 77440103 | E2: 8, Triq il-Laring, Attard, ATD 2531 Malta | F2: Geomatix Surveying | G2: Does land surveying, 3D scanning and drone surveying
A3: surveyor | B3: CM Surveying | C3: chris@cmsurveying.com.mt | D3: 99057464 | E3: No. 2, Triq Papa Piju XII, Birkirkara, Malta. | F3: https://www.cmsurveying.com/ | G3: They also offer courses
A4: surveyor | B4: Matsurv & Associates Ltd | C4: info@matsurv.eu | D4: 9949 5407 | E4: 89, Suite 1, ATL Business Centre, Triq Il-Kanun, Santa Venera, Malta | F4: https://www.facebook.com/matsurv/ | G4: Topographic surveys, 3D laser scanning,...
A5: surveyor | B5: NC Surveying | C5: ncsurveying23@gmail.com | D5: 7713 1010 | E5: NC Surveying 1 Joelle Triq Dun Guzepp Demicoli , Ghaxaq, Malta
A6: surveyor | B6: Alan Micallef Surveying Services | C6: alan@micallefsurveying.com | D6: 7970 7750 | E6: Alan Micallef Surveying Services 67 Flat 1 Triq Vince Dimech , Zurrieq, Malta ZRQ 2402 | F6: https://www.facebook.com/profile.php?id=100063536049877&utm_source=Yellow&utm_medium=Yellow-Website&utm_campaign=Landing-Page
A7: surveyor | B7: AR Surveying | C7: arsurveyingmalta@gmail.com | D7: 7941 1384 | E7: AR Surveying Triq it-Tahhan , B’Kara, Malta
A8: surveyor | B8: Atlas Surveying | C8: info@atlas-surveying.com | D8: 9998 7584 | E8: 182 Triq Bormla Paola, PLA 1905, MT, | F8: https://atlas-surveying.com/?utm_source=Yellow&utm_medium=Yellow-Website&utm_campaign=Landing-Page
A9: surveyor | B9: Impact Design | C9: impact.design.18@gmail.com | D9: 7904 9031 | E9: IMPACT design 56 Triq il-Vittmi tal-Gwerra Swatar , B’Kara, Malta
A10: surveyor | B10: Peter P Caruana | C10: lms@onvol.net | D10: 9949 6777 | E10: Peter P Caruana Shamrock Triq ta’ Giorni , San Giljan, Malta STJ 1615
A11: surveyor | B11: D&A Surveying | C11: surveying.da@gmail.com | D11: 9902 2336 | F11: https://www.checkyourtraders.com/listing/__trashed-19?fromCat=property-surveyor-surveying
A12: surveyor | B12: EllulSRV | C12: ellulsrv@gmail.com | D12: 9999 5037
A13: surveyor | B13: Malta Surveys (Shonnery Spiteri) | C13: maltasurveys.rs@gmail.com | D13: 9929 5479
A14: surveyor | B14: PSS DNA (Christopher Cassar) | C14: chris@pss-dna.com

Sheet Car Scrapping
A1: item | B1: name | C1: email | D1: phone number | E1: location | F1: website
A2: Car scrapping | B2: Tar-Robba Recycling Centre Ltd. | C2: johnghigo53@gmail.com | D2: 21683558, 99457162, 99493311 | E2: Limits of Kirkop
A3: Car scrapping | B3: Fredu Auto Parts | C3: freduautoparts@melita.com | D3: 27492222, 99490220 | E3: Plot, 6/7, Nassab Street, Qormi
A4: Car scrapping | B4: Gasparell Baling Plant Ltd. | C4: gasparell.b@gmail.com | D4: 21651475, 99495236 | E4: Ħal Far Ind Estate, Birzebbuga
A5: Car scrapping | B5: ELA Ltd. | C5: criszu75@gmail.com | D5: 21896023, 99495035, 99477294 | E5: 31, Wied Ghammieq Road Kalkara
A6: Car scrapping | B6: Auto Check Ltd. | C6: repairs@mile-end.mt | D6: 21444441, 79444441 | E6: 19/20/47, Triq l-Inginerija ma’Triq l-Iskola Teknika, Mriehel, Birkirkara
A7: Car scrapping | B7: DDE Attard | C7: info@ddeattard.com | D7: 21667857, 79442804 | E7: Scrap Lane, Valletta Road, Luqa, LQA 1764
A8: Car scrapping | B8: Roc-A-Go Services Ltd | C8: rocagoltd@gmail.com | D8: 21697766 | E8: Triq Tal-Barrani, Zejtun
A11: PROCEDURE WITH TM
A12: TM will only de-register and scrap a vehicle if the owner presents a certificate of desctruction issued by an approved desctruction facility.
A13: The authorised desctruction facility will issue a Certificate of Destruction. The certificate must be presented to TM during the scrapping process.
A15: AFTER the vehicle is taken to the treatment facility, the registered owner must call personally at the offices of TM and present the following documents:
A16: 1. Logbook
A17: 2. Registration number plate
A18: 3. Circulation license disc
A19: 4. Application form VEH13
A20: 5. Vehicle desctruction certificate
A22: CALL THE ABOVE AND ASK THEM TO EXPLAIN WHAT THE PROCESS IS AND HOW IT WORKS SO WE GET MORE INFO

Sheet Sills
A1: item | B1: supplier | C1: email | D1: phone number | E1: location | F1: website
A2: window sills | B2: design hub Store Malta | C2: info@designhubmalta.com.mt | D2: 99441703 | E2: 59 triq Domenico Cachia ,Birkirkara BKR 4019 ,MALTA | F2: designhubstores.com
A3: window sills | B3: Soll Malta | C3: info@soll.mt | D3: 21234567 | E3: triq il-Kalkara , Marsa , Malta | F3: soll.mt
A4: window sills | B4: Rabat marbles | C4: info@rabatmarbles.com | D4: 21456789 | E4: triq-il-Kbira , Rabat ,Malta | F4: rabatmarbles.com
A5: window sills | B5: Lawrence Fenech Ltd | C5: info@lawrencefenech.com | D5: 21345678 | E5: triq il-Labour ,Birkirkara, Malta | F5: lawrencefenech.com
A6: window sills | B6: AM Projects Malta | C6: info@pvc.com.mt | D6: 21654321 | E6: triq il-Ferrovija, Ħamrun, Malta | F6: pvc.com.mt
A7: window sills | B7: Finestral Malta | C7: info@finestralmalta.com | D7: 21468789 | E7: Triq il-Kostituzzjoni, Mosta, Malta | F7: finestralmalta.com
A8: window sills | B8: Building Materials Supplies Ltd(BMS Malta ) | C8: bmsltdmalta@gmail.com | D8: 21466668 | E8: Mdina Road, Qormi QRM 9011, Malta | F8: bms-malta.com
A9: window sills | B9: Graham Aluminium & Sons Ltd | C9: info@grahamaluminium.com | D9: 99994120 | E9: Mdina Road, Qormi QRM 9011, Malta | F9: grahamaluminium.com
A10: window sills | B10: Meli Bugeja Ltd | C10: info@melibugeja.com.mt | D10: 21444348 | E10: Triq il-Mithna,Qormi | F10: meliobugeja.com.mt
A11: window sills | B11: window World International | C11: info@windowworldinternational.net | D11: 2347 2994 | E11: Zircon Suites, Triq ta' Zejfa, Mosta, Malta | F11: windowworld.eu
A12: window sills | B12: Wilga Stores | C12: wilgastores@gmail.com | D12: 21897912 | E12: Wilga Street, Luqa LQA 1530, Malta | F12: wilgastores.com
A13: window sills | B13: Nicholas aluminium | C13: info@nicholas.mt | D13: 21464761 | E13: 33,Angelo A,Melilli ,HAz Zebugg ZBG 2802 | F13: nicholas.mt
A14: window sills | B14: Dingli Aluminium | C14: info@dinglialuminium.com | D14: 99472191 | E14: triq Anthony John Coleiro , hAL Qormi | F14: dinglialuminium.com
A15: window sills | B15: Schembri Marbles | C15: schembrimarbles@yahoo.com | D15: 21678608 | E15: Triq Dwardu Buttigieg ,Hal Ghaxaq,Malta GXQ 1253 | F15: findit.com.mt
A16: window sills | B16: Attard Bros | C16: info@attardbros.com
A17: window sills | B17: R Lautier | C17: info@rlautier.com
A18: window sills | B18: Floors of Stone | C18: sales@floorsofstone.com.mt
A19: window sills | B19: Desana Marbles | C19: info@desanamarbles.com
A20: window sills | B20: Cini Marbles | C20: info@cinimarbles.com
A21: window sills | B21: Seamless | C21: sales@seamless.com.mt
A22: window sills | B22: AMA Architectural Surfaces | C22: info@amaasurfaces.com
A23: window sills | B23: RGP Marbleware | C23: portellirennie@hotmail.com
A24: window sills | B24: Tiles and Marble | C24: tilesandmarbleinfo@gmail.com
A25: window sills | B25: Helmann Vella | C25: info@halmannvella.com
B26: Quality Stone Malta | C26: info@qualitystonemalta.com
B27: Marble Innovation | C27: sales@marbleinnovation.com
B28: C. Grech Marbles | D28: 9977 0099
B29: Show Tiles and More | C29: frankvassallo22@gmail.com
B30: Keith Bugeja Marble Works | C30: keithbugeja@hotmail.com

Sheet Waterproofing
A1: item | B1: supplier | C1: email | D1: phone number | E1: location | F1: website | G1: physical store | H1: installation | I1: delivery | J1: local supply | K1: import
A2: Waterproofing | B2: The Resin & Membrane Centre | C2: info@theresincentre.com | D2: 2747 7647 | E2: 264, Old Railway Track Santa Venera | F2: https://theresincentre.com/contact-us/ | G2: yes | H2: yes | I2: yes | J2: no | K2: yes
A3: Waterproofing | B3: Kenda Waterproofing | C3: kwaterproofing@melita.com | D3: 7972 9967 | E3: 24, Triq Indri Micallef,Luqa, Malta | F3: https://www.kendawaterproofing.com/contactV3.html# | G3: no | H3: yes | I3: yes | J3: yes | K3: no
A4: Waterproofing | B4: AG Waterproofing Services | C4: alexgrech.waterproofing@gmail.com | D4: 99 879 221 | E4: 2, Triq tal-Habaq, Luqa, Malta | F4: https://www.agwaterproofingmalta.com/ | G4: no | H4: yes | I4: yes
A5: Waterproofing | B5: CP Waterproofing | C5: colin@cpwaterproofing.com | D5: 99 445 181 | E5: Garage No 3, Pjazza l-Eroj,Swatar B'Kara BKR 4250 | F5: https://www.cpwaterproofing.com/ | G5: no | H5: yes | I5: yes | J5: yes | K5: no
A6: Waterproofing | B6: Air Solutions | C6: airsolutions@ezee.mt | D6: 7777 5495 | E6: 58, Donato del Piano Street, Zurrieq,ZRQ 2240 | F6: https://www.airsolutionslimited.com/ | G6: no | H6: yes | I6: yes | J6: yes | K6: no
A7: Waterproofing | B7: TN Waterproofing Services Ltd | C7: tnwaterproof@gmail.com | D7: 99 495 864 | E7: Cherry Blossom Triq Lorenzo Manche’, Attard, ATD 2906 | G7: no | H7: yes | I7: yes | J7: yes | K7: no
A8: Waterproofing | B8: Maximum Waterproofing | C8: danielschembri71@gmail.com | D8: 99 474 204 | E8: 102 Block A Flat 2 Triq Lapsi, Siggiewi | F8: https://www.fb.com/maximumwaterproofingmalta/ | G8: no | H8: yes | I8: yes | J8: yes | K8: no
A9: Waterproofing | B9: De Valtech | C9: info@devalier.com.mt | D9: 2149 1111 | E9: The Old Factory, San Gwakkin Str, Zone 3, Central Business District, Mriehel, B’kara, CBD 3030, Malta | F9: https://www.dv.mt/de-valtech-category/waterproofing/ | G9: yes | H9: yes | I9: yes | J9: no | K9: yes
A10: Waterproofing | B10: WP ltd | C10: wp.ltd123@gmail.com | D10: 99 445 527 | E10: WP Ltd Marcelle Triq ix-Xitwa , Qormi, Malta QRM 5234 | F10: https://www.wpmalta.com/?utm_source=Yellow&utm_medium=Yellow-Website&utm_campaign=Landing-Page | G10: no | H10: yes | I10: yes | J10: yes | K10: no
A11: Waterproofing | B11: 389 co Ltd | C11: info@389.com.mt | D11: 21 445 152 | E11: Three eight nine Co ltd (389 co Ltd) 22, 26 Triq Dun Xand Cortis , B’Kara, Malta BKR 1531 | G11: yes | H11: yes | I11: yes | J11: no | K11: yes
A12: Waterproofing | B12: C & Plastering | C12: clintsaliba3@gmail.com | D12: 79 256 240 | E12: C & R Plastering Trejqet il-Barrieri , Zurrieq, Malta ZRQ 3602 | F12: https://www.yellow.com.mt/c-r-plastering/waterproofing-contractors/ | G12: yes | H12: yes | I12: yes | J12: yes | K12: no
A13: Waterproofing | B13: Mr Lee Waterproofing | C13: mrleewaterproofing26@gmail.com | D13: 7700 3333 | F13: https://www.facebook.com/mrleewaterproofing/ | G13: no | H13: yes | I13: yes | J13: yes | K13: no
A14: Waterproofing | B14: Kibitec | C14: contact@kibitec.com | D14: 7777 1522 | F14: https://kibitec.com/waterproof-membrane-malta/ | G14: yes | H14: yes | I14: yes | J14: no | K14: yes
A15: Waterproofing | B15: Azzopardi Waterproofing | C15: azzopardiwp@gmail.com | D15: 9949 2745 | E15: Azzopardi Waterproofing Ltd 67 Triq il-Belt Valletta , Attard, Malta ATD 9056 | F15: https://www.yellow.com.mt/azzopardi-waterproofing-ltd_waterproofing-contractors+attard/ | G15: no | H15: yes | I15: yes | J15: yes | K15: no
A16: Waterproofing | B16: CHR Home Improvements | C16: caruana.chris@hotmail.com | D16: 7947 7777 | E16: CHR home improvements Triq Mikielang Sapiano , Luqa, Malta LQA 1803 | F16: https://www.facebook.com/CHR.home.improvements/?utm_source=Yellow&utm_medium=Yellow-Website&utm_campaign=Landing-Page | G16: no | H16: yes | I16: yes | J16: yes | K16: no
A17: Waterproofing | B17: Coverite Waterproofing | C17: jasonmartin777@hotmail.com | D17: 79 003 897 | E17: Coverite Waterproofing 3 Pretty Lodge Pjazza San Leonardu , Mosta, Malta MST 1061 | F17: https://www.yellow.com.mt/coverite-waterproofing_waterproofing-contractors+mosta/ | G17: no | H17: yes | I17: yes | J17: yes | K17: no
A18: Waterproofing | B18: D & G Waterproofing Membrane | C18: jurgendalli@gmail.com | D18: 99 498 925 | G18: no | H18: yes | I18: yes | J18: yes | K18: no
A19: Waterproofing | B19: JM Vassallo Vibro Steel Ltd | C19: sales@jmvibro.com | G19: yes | H19: yes | I19: yes | J19: no | K19: yes
A20: Waterproofing | B20: Andew Vassallo | C20: info@andrewvassallo.com | G20: yes | H20: yes | I20: yes | J20: no | K20: yes
A21: Waterproofing | B21: Norob Installations | C21: norob@onvol.net | G21: yes | H21: yes | I21: yes | J21: yes | K21: yes
A22: Waterproofing | B22: Forever Waterproofing | C22: forever.waterproofing@gmail.com | G22: no | H22: yes | I22: yes | J22: yes | K22: no
A23: Waterproofing | B23: L.C Waterproofing | C23: ludvic1979@gmail.com | G23: no | H23: yes | I23: yes | J23: yes | K23: no
A24: Waterproofing | B24: Martin's Waterproofing | C24: vmhome@go.net.mt | G24: no | H24: yes | I24: yes | J24: yes | K24: no
A25: Waterproofing | B25: Matuel Waterproofing | C25: matuelwaterproofing@gmail.com | G25: no | H25: yes | I25: yes | J25: yes | K25: no
A26: Waterproofing | B26: MP Liquid Membrane | C26: michael.portelli81@gmail.com | G26: no | H26: yes | I26: yes | J26: yes | K26: no
A27: Waterproofing | B27: Thermaseal | C27: admin@thermasealmalta.com | G27: no | H27: yes | I27: yes | J27: no | K27: yes
A28: Waterproofing | B28: Rosman Waterproofing | C28: rosmanwaterproofing@hotmail.com | G28: no | H28: yes | I28: yes | J28: yes | K28: no
A29: Waterproofing | B29: Joseph Stivala | C29: jostiv@live.com | G29: no | H29: yes | I29: yes | J29: yes | K29: no
A30: Waterproofing | B30: BCF Solutions | C30: bcf_solutions@outlook.com | G30: no | H30: yes | I30: yes | J30: yes | K30: no
A31: Waterproofing | B31: OIJ - Leak Detection and Maintenance | C31: oijwatermaintenance@gmail.com | G31: no | H31: yes | I31: yes | J31: yes | K31: no
A32: Waterproofing

Sheet Surface finishes
A1: item | B1: supplier | C1: email | D1: phone number | E1: location | F1: website

Sheet Terrazzo Slabs
A1: item | B1: supplier | C1: email | D1: phone number | E1: location | F1: website | G1: physical store | H1: intallation | I1: delivery | J1: local supply | K1: import
A2: Terrazzo Slab | B2: Carra.design | C2: c.demirkiran@carradesign.com | D2: 7712 2494 | F2: https://www.facebook.com/p/Carradesign-100086413076922/ | G2: no | H2: yes | I2: yes | J2: yes | K2: no
A3: Terrazzo Slab | B3: Absolute | C3: info@absolute.com.mt | D3: 2141 7596 | F3: https://www.absolute.com.mt/terrazzo/ | G3: yes | H3: yes | I3: yes | J3: yes | K3: no
A4: Terrazzo | B4: Helmann Vella | C4: info@halmannvella.com | D4: 2143 3636 | F4: https://www.halmannvella.com/ | G4: yes | H4: yes | I4: yes | J4: yes | K4: yes
A5: Terrazzo | B5: Desana Marbles | C5: info@desanamarbles.com | D5: 2145 1350 | F5: https://www.desanamarbles.com/materials/terrazzo | G5: yes | H5: yes | I5: yes | J5: yes | K5: yes
B6: Marble Innovation | C6: sales@marbleinnovation.com | F6: https://www.marbleinnovation.com/contact | G6: yes | H6: yes | I6: yes | J6: yes | K6: yes
B7: Pitre Bathrooms | C7: info@jpitre.com | D7: 21463335 | F7: https://www.pitrebathrooms.com/contact-us | G7: yes | H7: no | I7: yes | J7: yes | K7: no
B8: Iperceramica | C8: msida@iperceramica.mt | G8: yes | H8: no | I8: yes | J8: no | K8: yes
B9: Rado Flooring | C9: info@radosystems.eu | F9: https://www.facebook.com/radoflooring/ | G9: no | H9: yes | I9: yes | J9: yes | K9: no
B10: Cordina | C10: steve@cordina.eu | F10: https://www.facebook.com/cordinamt/ | G10: no | H10: yes | I10: yes | J10: yes | K10: no
B11: MRCD | C11: info@mrcd.com.mt | F11: https://www.mrcd.com.mt/en/home.htm | G11: yes | H11: no | I11: yes | J11: no | K11: yes
B12: CP Marbles | C12: cpcamilleripatrick@gmail.com | F12: https://www.facebook.com/profile.php?id=100054506707941 | G12: yes | H12: yes | I12: yes | J12: yes | K12: yes
B13: Seamless Surfaces | C13: sales@seamless.com.mt | F13: https://www.facebook.com/seamlessmalta/ | G13: yes | H13: yes | I13: yes | J13: yes | K13: yes
C14: sales@floorsofstone.com.mt
C15: info@cgaleamarble.com
C16: info@chicliving.com.mt
C17: info@distincthomes.com.mt
C18: info@bfmarbles.com
C19: info@soll.mt

Sheet Washing Machines
A1: item | B1: supplier | C1: email | D1: phone number | E1: location | F1: website | G1: physical store | H1: installation | I1: delivery | J1: local supply | K1: import
A2: washing machines | B2: Flamingo malta | C2: info@flamingo.com.mt | D2: 21443333 | E2: Mrieħel, Malta | F2: flamingo.com.mt | G2: yes | H2: yes | I2: yes | J2: yes | K2: yes
A3: washing machines | B3: WashingMachinesMalta | C3: info@washingmachinesmalta.com | D3: 2732 0796 | E3: Distribution Warehouse Center, Qormi, Malta | F3: washingmachinesmalta.com | G3: no | H3: yes | I3: yes | J3: yes | K3: yes
A4: washing machines | B4: Top Choice | C4: info@topchoice.com.mt | D4: 2123 4567 | E4: Il-Ħamrun y San Pawl il-Baħar, Malta | F4: topchoice.com.mt | G4: yes | H4: yes | I4: yes | J4: yes | K4: yes
A5: washing machines | B5: Petroni Ltd. | C5: info@petroni.com.mt | D5: 2133 2233 | E5: Msida, Malta | F5: petroni.com.mt | G5: yes | H5: yes | I5: yes | J5: yes | K5: yes
A6: washing machines | B6: Teckline Discount Store | C6: info@teckline.com.mt | D6: 2124 5678 | E6: Il-Ħamrun, Malta | F6: teckline.com.mt | G6: yes | H6: yes | I6: yes | J6: yes | K6: yes
A7: washing machines | B7: . Sound Machine | C7: info@soundmachine.com.mt | D7: 2149 7111 | E7: Psaila Street, Birkirkara, Malta | F7: soundmachine.com.mt | G7: yes | H7: yes | I7: yes | J7: yes | K7: yes
A8: washing machines | B8: KCL Home Centre | C8: info@kcl.com.mt | D8: 2149 3285 / | E8: 22, Triq Sant' Elija, Birkirkara, Fleur-De-Lys, Malta BKR 4942 | F8: www.kcl.com.m | G8: yes | H8: yes | I8: yes | J8: yes | K8: yes
A9: washing machines | B9: JS Household | C9: info@jshousehold.com | D9: 2169 1334 | E9: 71, Triq Il-Buqexrem, Il-Fgura, Malta | F9: jshousehold.com | G9: yes | H9: yes | I9: yes | J9: yes | K9: yes
A10: washing machines | B10: Hotpoint Malta | C10: info@hotpointmalta.com | D10: 2343 6345 | E10: Valley Road, Birkirkara BKR9010, Malta | F10: hotpointmalta.com | G10: yes | H10: yes | I10: yes | J10: yes | K10: yes
A11: washing machines | B11: Lava.mt ( | C11: info@lava.mt | D11: -------------------- | E11: Zachary House, Marsa Industrial Estate, Marsa MRS 3000, Malta | F11: lava.mt | G11: no | H11: yes | I11: yes | J11: yes | K11: yes
A12: washing machines | B12: Crosscraft | C12: info@crosscraft.com.mt | D12: 2180 5805 | E12: Mriehel Bypass, Qormi, Malta | F12: crosscraft.com.mt | G12: yes | H12: yes | I12: yes | J12: yes | K12: yes
A13: washing machines | B13: Audio Malta | C13: info@audiomalta.com | D13: 2138 2876 | E13: 26C Triq Lispiera, Swieqi, Malta | F13: audiomalta.com | G13: yes | H13: no | I13: yes | J13: yes | K13: yes
A14: washing machines | B14: ElectroFix Malta | C14: info@electrofix.com.mt | D14: 2144 5555 | E14: Triq il-Kanun, Qormi, Malta | F14: https://www.electrofixgroup.com/ | G14: yes | H14: no | I14: yes | J14: yes | K14: yes
... A24: washing machines | B24: Freddie's Household | C24: freddies@onvol.net | D24: 2143 2863 | E24: Eucharistic Congress Road, Mosta, Malta | F24: ________ | G24: yes | H24: yes | I24: yes | J24: yes | K24: yes

Sheet Tumble Dryer
A1: item | B1: supplier | C1: email | D1: phone number | E1: location | F1: website | G1: physical store | H1: installation | I1: delivery | J1: local supply | K1: import
A2: Tumble Dryer | B2: Ventura General Gas Ltd | C2: adriangrech@venturamalta.com | D2: 21 677 798 | E2: BLB 021 Qasam Industrijali, Bulebel , Zejtun, Malta ZTN 3000 | F2: www.venturamalta.com | G2: yes | H2: yes | I2: yes | J2: yes | K2: yes
A3: Tumble Dryer | B3: Forestals | C3: info@forestals.com | D3: 2549 3000 | E3: Mrieħel Bypass, Birkirkara, Malta | F3: forestals.com | G3: yes | H3: yes | I3: yes | J3: yes | K3: yes
A4: Tumble Dryer | B4: AtoZ Electronics | C4: info@atoz.com.mt | D4: 2133 6600 | E4: Valley Road, Msida, Malta | F4: atoz.com.mt | G4: yes | H4: yes | I4: yes | J4: yes | K4: yes
A5: Tumble Dryer | B5: Crosscraft | C5: info@crosscraft.com.mt | D5: 2180 5805 | E5: Mriehel Bypass, Qormi, Malta | F5: crosscraft.com.mt | G5: yes | H5: yes | I5: yes | J5: yes | K5: yes
A6: Tumble Dryer | B6: Homemate | C6: customercare@homemate.com.mt | D6: 2326 2000 | E6: Mriehel | F6: https://www.homemate.com.mt/product/midea-free-standing-tumble-dryer-white-10kg-a-class | G6: yes | H6: no | I6: yes | J6: yes | K6: yes
A7: Tumble Dryer | B7: Hotpoint Malta | C7: info@hotpointmalta.com | D7: 2343 6345 | E7: Valley Road, Birkirkara BKR9010, Malta | F7: hotpointmalta.com | G7: yes | H7: yes | I7: yes | J7: yes | K7: yes
A8: Tumble Dryer | B8: KCL Home Centre | C8: info@kcl.com.mt | D8: 2149 3285 / | E8: 22, Triq Sant' Elija, Birkirkara, Fleur-De-Lys, Malta BKR 4942 | F8: www.kcl.com.m | G8: yes | H8: yes | I8: yes | J8: yes | K8: yes
A9: Tumble Dryer | B9: Sound Machine | C9: info@soundmachine.com.mt | D9: 2149 7111 | E9: Psaila Street, Birkirkara, Malta | F9: soundmachine.com.mt | G9: yes | H9: yes | I9: yes | J9: yes | K9: yes
A10: Tumble Dryer | B10: Petroni Ltd. | C10: info@petroni.com.mt | D10: 2133 2233 | E10: Msida, Malta | F10: petroni.com.mt | G10: yes | H10: yes | I10: yes | J10: yes | K10: yes
A11: Tumble Dryer | B11: Top Choice | C11: info@topchoice.com.mt | D11: 2123 4567 | E11: Il-Ħamrun y San Pawl il-Baħar, Malta | F11: topchoice.com.mt | G11: yes | H11: yes | I11: yes | J11: yes | K11: yes
A12: Tumble Dryer | B12: Flamingo malta | C12: info@flamingo.com.mt | D12: 21443333 | E12: Mrieħel, Malta | F12: flamingo.com.mt | G12: yes | H12: yes | I12: yes | J12: yes | K12: yes
A13: Tumble Dryer | B13: Vitel Home | C13: info@vitelmalta.com | D13: 21377172 | E13: Triq R. Caruana Dingli San Gwann, SGN 1035 Malta. | F13: https://vitelmalta.com/shop/domestic-appliances/laundry-appliances/tumble-dryers/keen-tumble-dryer-10kg-dhb1053ba/ | G13: yes | H13: yes | I13: yes | J13: yes | K13: yes
A14: Tumble Dryer | B14: Triple A | C14: info@triplea.mt | D14: 21257346 | E14: Triple A Luqa 1, St. Thomas Street,, Ħal Luqa LQA 9031 | F14: https://triplea.mt/contactus | G14: yes | H14: yes | I14: yes | J14: yes | K14: yes
A15: Tumble Dryer | B15: Paulson | C15: paulsonmalta@gmail.com | D15: 2166 3329 | E15: Paulson Home & Hi-Fi Centre, Bir Deheb Road, Zejtun, Malta | F15: https://www.paulson.com.mt/en/shop/webshop/683/concorde-10kg-tumble-dryer---condenser | G15: yes | H15: yes | I15: yes | J15: yes | K15: yes
A16: Tumble Dryer | B16: ProChimps | C16: info@prochimps.com | D16: 9978 5765 | E16: Santa Venera, Canon Road, Malta | F16: https://prochimps.com/collections/tumble-dryer | G16: yes | H16: yes | I16: yes | J16: yes | K16: yes
A17: Tumble Dryer | B17: Right Deal | G17: yes | H17: yes | I17: yes | J17: yes | K17: yes
A18: Tumble Dryer | B18: Paulson | G18: yes | H18: yes | I18: yes | J18: yes | K18: yes

Sheet Gypsum
A1: item | B1: supplier | C1: email | D1: phone number | E1: location | F1: website | G1: physical store | H1: installation | I1: delivery | J1: local supply | K1: import
A2: gypsum | B2: Summit Importers & Distributors | C2: sales@summit.com.mt | D2: 2141 1206 | E2: Xwieki Road, Triq Tal-Balal, Tal-Balal, Iklin, IKL 9013, Malta | F2: www.summit.com.mt | G2: yes | H2: no | I2: yes | J2: no | K2: yes
A3: gypsum | B3: CA Gypsum | C3: cagypsum@onvol.net | D3: 2741 8713 | E3: 107, Triq L-Istadju, Gzira, GZR 1301, Malta | F3: www.cagypsummalta.com | G3: no | H3: yes | I3: yes | J3: yes | K3: no
A4: gypsum | B4: D Gypsum and Lights | C4: dgypsumandlights@gmail.com | D4: 2705 2100 | E4: Triq Hal Tarxien, Il-Gudja, Malta | F4: www.dgypsumworks.com | G4: no | H4: yes | I4: yes | J4: yes | K4: no
A5: gypsum | B5: Grant's Gypsum Work | C5: grantgypsumwork@gmail.com | D5: 7945 0373 | E5: 13, Triq Ignazio Saverio Mifsud, Birkirkara, BKR1017, Malta | F5: www.grantsgypsumwork.com | G5: no | H5: yes | I5: yes | J5: yes | K5: no
A6: gypsum | B6: Galea & Tonna Gypsum Works | C6: gplusgypsum@gmail.com | D6: 9980 4706 | E6: 43, Triq Qrajten, Tal-Pieta', Malta | F6: --------------------- | G6: no | H6: yes | I6: yes | J6: yes | K6: no
A7: gypsum | B7: Buffa Malta | C7: buffamalta@t4bservices.com | D7: 2148 5629 | E7: Valletta Road, Qormi (frente a Maltapost), Malta | F7: --------------------- | G7: yes | H7: no | I7: yes | J7: no | K7: yes
A8: gypsum | B8: P J Gypsum Works | C8: pjgypsumworks@gmail.com | D8: 9982 6705 | E8: 94, Emmant, Triq Salvu Aquilina, Mosta, MST 3162, Malta | F8: www.pjgypsumworks.com | G8: no | H8: yes | I8: yes | J8: yes | K8: no
A9: gypsum | B9: Pierre Chircop Gypsum Works | C9: pchircop76@gmail.com | D9: 7944 8833 | E9: Marsaxlokk, Malta | F9: www.summit.com.mt | G9: no | H9: yes | I9: yes | J9: yes | K9: no
A10: gypsum | B10: Grima Interiors | C10: grimainteriors@hotmail.com | D10: 9988 8272 / | E10: Triq Luret Cutajar, Ħaż-Żebbuġ ZBG 273, Malta | F10: www.grimainteriors.com | G10: no | H10: yes | I10: yes | J10: yes | K10: no
A11: gypsum | B11: Donovan Plastering | C11: donovanplastermalta@gmail.com | D11: 7727 0833 | E11: 49 Triq Spadaro, Ħaż-Żabbar, Malta | F11: www.donovan-plastering.com | G11: no | H11: yes | I11: yes | J11: yes | K11: no
A12: gypsum | B12: JCR Imports Ltd | C12: jattard@jcrimports.com.mt | D12: 2144 2466 | E12: Triq In-Negozju, Mrieħel, Birkirkara BKR 3000, Malta | F12: www.jcrimports.com.mt | G12: yes | H12: no | I12: yes | J12: no | K12: yes
... A15: gypsum | B15: Mediterranean Building Finishes Ltd | C15: info@mbfmalta.com | D15: 2137 4454 | E15: Riviera Court/2, Triq Forrest, San Ġiljan, Malta | F15: www.mbfmalta.com | G15: no | H15: yes | I15: yes | J15: yes | K15: no
A16: Gypsum | B16: GRF Malta | C16: info@grfmalta.com | D16: 21377378 | E16: 117 Triq L-Assemblea Nazzjonali, San Gwann SGN 3034, Malta | F16: https://grfmalta.com/ | G16: no | H16: yes | I16: yes | J16: yes | K16: no
A17: Gypsum | B17: O&M Gypsum | C17: oandmgypsum.com@gmail.com | D17: 2149 2920 | E17: 69, Triq John Borg, Birkirkara, Malta BKR 1284 | F17: https://www.findit.com.mt/en/directory/listings/441/oandampm-gypsum-malta.htm | G17: no | H17: yes | I17: yes | J17: yes | K17: no
A18: Gypsum | B18: Perfectum | C18: Info@perfectum.mt | D18: 9921 5215 | E18: Valletta, Malta | F18: https://www.facebook.com/perfectummt/ | G18: no | H18: yes | I18: yes | J18: yes | K18: no
A19: Gypsum | B19: GAD Finishings | C19: alex@gad.com.mt | D19: 9947 2226 | E19: 21, Triq Gellewza Sewda, Midland Park, D7 Burmarrad Road, Burmarrad LO Naxxar Malta | F19: https://www.gad.com.mt/ | G19: no | H19: yes | I19: yes | J19: yes | K19: no
A20: Gypsum | B20: Xuereb Instalations Ltd | C20: xil@xuerebinstall.com | D20: 99492278 | E20: Xuereb Installations Ltd. Tal-Hlas Road, Qormi QRM 5011. Malta | F20: https://xuerebinstall.com/ | G20: no | H20: yes | I20: yes | J20: yes | K20: no
A21: Gypsum | B21: JG Gypsum | C21: josephgiordano54@gmail.com | D21: 79939898 | E21: Hal Mula Street, Garage number 5. | F21: https://josephgiordano54.wixsite.com/josephgiordano | G21: no | H21: yes | I21: yes | J21: yes | K21: no
A22: Cement Boards | B22: Meli Bugeja | C22: info@melibugeja.com.mt | D22: 7908 7476 | F22: melibugeja.com.mt | G22: yes | H22: no | I22: yes | J22: no | K22: yes
A23: Gypsum | B23: Deo's Interiors | C23: lukeattard89@gmail.com | D23: 9988 7158 | F23: https://www.facebook.com/profile.php?id=61560664902130 | G23: no | H23: yes | I23: yes | J23: yes | K23: no

Sheet Cubicle Partitions
A1: item | B1: supplier | C1: email | D1: phone number | E1: location | F1: website | G1: other
A2: partition | B2: CRC Group | C2: marketing@crcmalta.com | D2: 7741 9400 | F2: https://www.crcmalta.com/shop/category/partitions-cubicles-for-showers-or-w-cs-656
A3: partition | B3: Quality Postform | C3: qualitypostform@gmail.com | D3: 2123 8054 | F3: https://www.qualitypostform.com/en/products/products/21/algonquin-anti-vandal-cubicles
A4: partition | B4: ProBuild | C4: sales@probuildmalta.com | D4: 7741 9500 | F4: https://www.probuildmalta.com/
A5: partition | B5: BSL Lifestyles | C5: sales@bsl-lifestyles.com | F5: https://bsl-lifestyles.com/product-category/partitions-panels/?offset=4
A6: partition | B6: Da Valier | C6: info@devalier.com.mt | F6: https://www.dv.mt/showroom-category/office-partitions/
A7: partition | B7: Xuereb Installations | C7: xil@xuerebinstall.com | F7: https://xuerebinstall.com/our-service/demountable-partitions/
A8: partition | B8: Trends | C8: info@trendsltdmalta.com | F8: https://www.trendsltdmalta.com/products/commercial-bathrooms/cubicles/
A9: partition | B9: Dimech Enterprises | C9: sales@dimech-ent.com | F9: https://www.dimech-ent.com/
B10: Sham Decorations | D10: 9914 8332
B11: Shaker | C11: sales@shaker.com.mt
B12: Jialifu (CHINA) | C12: sales@jialifucn.com | F12: https://www.jialifucn.com/compact-laminate-toilet-partitions/

Sheet Site Clearance
A1: item | B1: supplier | C1: email | D1: phone number | E1: location | F1: website
A2: Tile remover/torba, Carting away of materials | B2: Fardell Home Maintenance | C2: fardellhonda@gmail.com | D2: 9968 5377 | E2: 111-113 Hompesch Road, Fgura | F2: https://fardellhonda.wixsite.com/fardellmaintenance
A3: Carting away | B3: Vella Brothers & Sons | C3: info@vellabrothersandsons.com | D3: 2145 5674 / 7945 5674 | E3: TA' DMIEREK QUARRY c/o Maghlaq Quarry - Panoramic Road, Qrendi | F3: https://vellabrothersandsons.com/index.html

Sheet Industrial Shelving
A1: item | B1: supplier | C1: email | D1: phone number | E1: location | F1: website | G1: physical store | H1: installation | I1: delivery | J1: local supply | K1: import
A2: industrial shelving | B2: Ennegi Enterprises Ltd | C2: sales@ennegiltd.com | D2: 2146 3517 | E2: 237, Triq Hal Qormi, Marsa, MRS 9045, Malta | F2: www.ennegiltd.com | G2: yes | H2: yes | I2: yes | J2: no | K2: yes
A3: industrial shelving | B3: Storage Systems Ltd | C3: storagesys@vol.net.mt | D3: 2148 8450 | E3: KW12, Zona Industrijali Ta' Kordin, Coradino, Paola, Malta | F3: www.storagesystems.com.mt | G3: yes | H3: yes | I3: yes | J3: no | K3: yes
A4: industrial shelving | B4: Caravel Ltd | C4: dario@caravelmalta.com | D4: 2134 0289 | E4: ‘Raycop’, Plot 13/15, Sqaq iz-Ziemel, Handaq, Qormi QRM-4003, Malta | F4: www.caravelmalta.com | G4: yes | H4: yes | I4: yes | J4: no | K4: yes
A5: industrial shelving | B5: AGP Systems Ltd | C5: info@agps.com.mt | D5: 2279 2123 | E5: Zamco Buildings, Triq Il-Mithna, Hal Qormi, QRM 3103, Malta | F5: www.agps.com.mt | G5: yes | H5: yes | I5: yes | J5: no | K5: yes
A6: industrial shelving | B6: T4B Services Ltd | C6: info@t4bservices.com | D6: 2123 7555 | E6: Canter Business Centre, Triq Patri Felicjan Bilocca, Il-Marsa, Malta | F6: www.t4bservices.com | G6: yes | H6: yes | I6: yes | J6: no | K6: yes
A7: industrial shelving | B7: ALFEN Displays | C7: alfen@maltanet.net | D7: 2122 5721 | E7: 96, Triq Il-Kbira San Guzepp, Il-Hamrun, Malta | F7: www.alfendisplays.com | G7: yes | H7: yes | I7: yes | J7: no | K7: yes
A8: industrial shelving | B8: UDS Limited (Upward Door Systems Ltd) | C8: uds@maltanet.net | D8: 2156 4456 | E8: Factory C, Triq L-Industrija, Ix-Xewkija (Gozo) XWK 3000, Malta | F8: www.udsmalta.com | G8: yes | H8: yes | I8: yes | J8: no | K8: yes
A9: industrial shelving | B9: 360 Retail Supplies Ltd | C9: info@360rs.com.mt | D9: 2713 9608 | E9: 360 Business Center, Mdina Road, Ħaż-Żebbuġ, ZBG 9014, Malta | F9: www.360retailsupplies.com | G9: yes | H9: yes | I9: yes | J9: no | K9: yes
A10: industrial shelving | B10: deValtech Co Ltd | C10: info@devaltech.com | D10: 7942 5055 | E10: de Valtech Building, San Gwakkin Street, Zone 3, Central Businees District, Mriehel CBD 3030 Birkirkara, Malta | F10: https://www.dv.mt/de-valtech/ | G10: yes | H10: yes | I10: yes | J10: no | K10: yes
